Workbook

Sheet Overview
A1: FOTC 2027 — 26-WEEK PREP · NOVICE TEAM · MIKE
A2: Layered on top of CrossFit classes as extra work. Coastal Qualifier: Oct 1–28, 2026 — workouts release Thursdays 7pm ET, scores due following Wednesday 9pm ET, 5 scores over 4 weeks (one surprise double week). Championship: Jan 15–17, 2027, Charleston Convention Center (teams compete Sat afternoon into Sunday, Jan 16–17). Registration opens Aug 1 — register Novice Team — BOTH partners register.
A4: WK | B4: DATES | C4: BLOCK | D4: FOCUS | E4: KEY NOTES
A5: 1 | B5: Jul 20–Jul 26 | C5: B1 · Base | D5: Wave 1 begins + BASELINE TESTS | E5: Test: strict pull-ups, strict & kipping HSPU max sets, 2k row, 4x400m
A6: 2 | B6: Jul 27–Aug 02 | C6: B1 · Base | D6: Wave 1 week 2 · strict gymnastics volume | E6: Aug 1: Coastal Qualifier registration opens — REGISTER (Novice Team — both partners)
A7: 3 | B7: Aug 03–Aug 09 | C7: B1 · Base | D7: Wave 1 week 3 (heaviest) · aerobic base
A8: 4 | B8: Aug 10–Aug 16 | C8: B1 · Base | D8: DELOAD | E8: Cut accessory volume ~1 set everywhere; easy Z2 Wednesday
A9: 5 | B9: Aug 17–Aug 23 | C9: B1 · Base | D9: Heavy-for-day singles · back-offs | E9: End of base — strict numbers should be moving
A10: 6 | B10: Aug 24–Aug 30 | C10: B2 · Build | D10: Heavy singles + wall-walk progression starts | E10: Fri shifts to push press; Sat = qualifier-style sims
A11: 7 | B11: Aug 31–Sep 06 | C11: B2 · Build | D11: Build week · HS walk + barbell cycling | E11: Sat sim = last year's Qualifier WK4, Novice version (KTC/BJO/DL 185)
A12: 8 | B12: Sep 07–Sep 13 | C12: B2 · Build | D12: Build week | E12: Mon Sep 7 = Labor Day — Whitten (tradition)
A13: 9 | B13: Sep 14–Sep 20 | C13: B2 · Build | D13: Last hard build week | E13: Sat sim = last year's Qualifier WK5, Novice version (SU/jumping-PU descender)
A14: 10 | B14: Sep 21–Sep 27 | C14: B2 · Taper | D14: QUALIFIER TAPER — volume −40% | E14: Rehearse the warm-up protocol · confirm judge/camera/Comp Corner login
A15: 11 | B15: Sep 28–Oct 04 | C15: B3 · Qualifier | D15: QUALIFIER WK1 | E15: Releases Thu Oct 1, 7pm ET · attempt Fri · due Wed Oct 7
A16: 12 | B16: Oct 05–Oct 11 | C16: B3 · Qualifier | D16: QUALIFIER WK2 | E16: Releases Thu Oct 8 · due Wed Oct 14 · watch for surprise double week
A17: 13 | B17: Oct 12–Oct 18 | C17: B3 · Qualifier | D17: QUALIFIER WK3 | E17: Releases Thu Oct 15 · due Wed Oct 21
A18: 14 | B18: Oct 19–Oct 25 | C18: B3 · Qualifier | D18: QUALIFIER WK4 | E18: Releases Thu Oct 22 · due Wed Oct 28
A19: 15 | B19: Oct 26–Nov 01 | C19: B3 · Qualifier | D19: Final scores + recovery transition | E19: Scores final Wed Oct 28 9pm · save all videos — FOTC emails video requests to qualifiers
A20: 16 | B20: Nov 02–Nov 08 | C20: B4 · Rebuild | D20: Volume reset + WEAKNESS AUDIT | E20: Retest gymnastics max sets — program weeks 17–18 attack what the qualifier exposed
A21: 17 | B21: Nov 09–Nov 15 | C21: B4 · Rebuild | D21: Strength build · snatch tech · threshold engine
A22: 18 | B22: Nov 16–Nov 22 | C22: B4 · Rebuild | D22: Heaviest rebuild week · clean tech
A23: 19 | B23: Nov 23–Nov 29 | C23: B4 · Rebuild | D23: THANKSGIVING DELOAD | E23: Travel-friendly sessions · Whitten or turkey trot Thu Nov 26
A24: 20 | B24: Nov 30–Dec 06 | C24: B4 · Test | D24: MAX TESTING WEEK | E24: New 1RMs: BS/Bench/SP/FS + C&J/Snatch — UPDATE MAXES TAB
A25: 21 | B25: Dec 07–Dec 13 | C25: B5 · Champ Prep | D25: Event simulations begin (off new maxes) | E25: Event 2+3 back-to-back sim Friday
A26: 22 | B26: Dec 14–Dec 20 | C26: B5 · Champ Prep | D26: Heavy mixed-object + capacity sims
A27: 23 | B27: Dec 21–Dec 27 | C27: B5 · Champ Prep | D27: CHRISTMAS — condensed 4 sessions | E27: Short and sharp; protect intensity, drop volume
A28: 24 | B28: Dec 28–Jan 03 | C28: B5 · Champ Prep | D28: FULL 2-DAY COMPETITION SIMULATION | E28: Sat Jan 2 + Sun Jan 3 · rehearse warm-ups, food, between-event recovery
A29: 25 | B29: Jan 04–Jan 10 | C29: B6 · Peak | D29: Sharpen — volume −50%, crisp primers | E29: Sleep 8+ · keep eating at maintenance · nothing new
A30: 26 | B30: Jan 11–Jan 17 | C30: B6 · Peak | D30: COMPETE — FOTC Championship | E30: Thu rest · Fri travel + shakeout · Sat–Sun COMPETE (teams: Sat afternoon → Sun, Jan 16–17)

Sheet Maxes
A1: LIFT | B1: 1RM (lb) | C1: Notes
A2: Back Squat | B2: 275
A3: Front Squat | B3: 225
A4: Bench Press | B4: 195
A5: Strict Press | B5: 135
A6: Deadlift | B6: 315
A7: Clean & Jerk | B7: 205 | C7: ESTIMATE — test Week 20 and update
A8: Snatch | B8: 145 | C8: ESTIMATE — test Week 20 and update
A9: PARTNER: save your own copy of this file and enter YOUR 1RMs above — every load in every week recalculates automatically.
A10: PERCENTAGE CHART (auto — update 1RMs above and everything recalculates; rounded to 5 lb)
A11: % | B11: Back Squat | C11: Front Squat | D11: Bench Press | E11: Strict Press | F11: Deadlift | G11: Clean & Jerk | H11: Snatch
A12: 0.95 | B12: =MROUND($B$2*$A12,5) -> 260 | C12: =MROUND($B$3*$A12,5) -> 215 | D12: =MROUND($B$4*$A12,5) -> 185 | E12: =MROUND($B$5*$A12,5) -> 130 | F12: =MROUND($B$6*$A12,5) -> 300 | G12: =MROUND($B$7*$A12,5) -> 195 | H12: =MROUND($B$8*$A12,5) -> 140
A13: 0.925 | B13: =MROUND($B$2*$A13,5) -> 255 | C13: =MROUND($B$3*$A13,5) -> 210 | D13: =MROUND($B$4*$A13,5) -> 180 | E13: =MROUND($B$5*$A13,5) -> 125 | F13: =MROUND($B$6*$A13,5) -> 290 | G13: =MROUND($B$7*$A13,5) -> 190 | H13: =MROUND($B$8*$A13,5) -> 135
A14: 0.9 | B14: =MROUND($B$2*$A14,5) -> 250 | C14: =MROUND($B$3*$A14,5) -> 205 | D14: =MROUND($B$4*$A14,5) -> 175 | E14: =MROUND($B$5*$A14,5) -> 120 | F14: =MROUND($B$6*$A14,5) -> 285 | G14: =MROUND($B$7*$A14,5) -> 185 | H14: =MROUND($B$8*$A14,5) -> 130
A15: 0.875 | B15: =MROUND($B$2*$A15,5) -> 240 | C15: =MROUND($B$3*$A15,5) -> 195 | D15: =MROUND($B$4*$A15,5) -> 170 | E15: =MROUND($B$5*$A15,5) -> 120 | F15: =MROUND($B$6*$A15,5) -> 275 | G15: =MROUND($B$7*$A15,5) -> 180 | H15: =MROUND($B$8*$A15,5) -> 125
A16: 0.85 | B16: =MROUND($B$2*$A16,5) -> 235 | C16: =MROUND($B$3*$A16,5) -> 190 | D16: =MROUND($B$4*$A16,5) -> 165 | E16: =MROUND($B$5*$A16,5) -> 115 | F16: =MROUND($B$6*$A16,5) -> 270 | G16: =MROUND($B$7*$A16,5) -> 175 | H16: =MROUND($B$8*$A16,5) -> 125
A17: 0.825 | B17: =MROUND($B$2*$A17,5) -> 225 | C17: =MROUND($B$3*$A17,5) -> 185 | D17: =MROUND($B$4*$A17,5) -> 160 | E17: =MROUND($B$5*$A17,5) -> 110 | F17: =MROUND($B$6*$A17,5) -> 260 | G17: =MROUND($B$7*$A17,5) -> 170 | H17: =MROUND($B$8*$A17,5) -> 120
A18: 0.8 | B18: =MROUND($B$2*$A18,5) -> 220 | C18: =MROUND($B$3*$A18,5) -> 180 | D18: =MROUND($B$4*$A18,5) -> 155 | E18: =MROUND($B$5*$A18,5) -> 110 | F18: =MROUND($B$6*$A18,5) -> 250 | G18: =MROUND($B$7*$A18,5) -> 165 | H18: =MROUND($B$8*$A18,5) -> 115
A19: 0.775 | B19: =MROUND($B$2*$A19,5) -> 215 | C19: =MROUND($B$3*$A19,5) -> 175 | D19: =MROUND($B$4*$A19,5) -> 150 | E19: =MROUND($B$5*$A19,5) -> 105 | F19: =MROUND($B$6*$A19,5) -> 245 | G19: =MROUND($B$7*$A19,5) -> 160 | H19: =MROUND($B$8*$A19,5) -> 110
A20: 0.75 | B20: =MROUND($B$2*$A20,5) -> 205 | C20: =MROUND($B$3*$A20,5) -> 170 | D20: =MROUND($B$4*$A20,5) -> 145 | E20: =MROUND($B$5*$A20,5) -> 100 | F20: =MROUND($B$6*$A20,5) -> 235 | G20: =MROUND($B$7*$A20,5) -> 155 | H20: =MROUND($B$8*$A20,5) -> 110
A21: 0.725 | B21: =MROUND($B$2*$A21,5) -> 200 | C21: =MROUND($B$3*$A21,5) -> 165 | D21: =MROUND($B$4*$A21,5) -> 140 | E21: =MROUND($B$5*$A21,5) -> 100 | F21: =MROUND($B$6*$A21,5) -> 230 | G21: =MROUND($B$7*$A21,5) -> 150 | H21: =MROUND($B$8*$A21,5) -> 105
A22: 0.7 | B22: =MROUND($B$2*$A22,5) -> 195 | C22: =MROUND($B$3*$A22,5) -> 160 | D22: =MROUND($B$4*$A22,5) -> 135 | E22: =MROUND($B$5*$A22,5) -> 95 | F22: =MROUND($B$6*$A22,5) -> 220 | G22: =MROUND($B$7*$A22,5) -> 145 | H22: =MROUND($B$8*$A22,5) -> 100
A23: 0.675 | B23: =MROUND($B$2*$A23,5) -> 185 | C23: =MROUND($B$3*$A23,5) -> 150 | D23: =MROUND($B$4*$A23,5) -> 130 | E23: =MROUND($B$5*$A23,5) -> 90 | F23: =MROUND($B$6*$A23,5) -> 215 | G23: =MROUND($B$7*$A23,5) -> 140 | H23: =MROUND($B$8*$A23,5) -> 100
... A26: 0.6 | B26: =MROUND($B$2*$A26,5) -> 165 | C26: =MROUND($B$3*$A26,5) -> 135 | D26: =MROUND($B$4*$A26,5) -> 115 | E26: =MROUND($B$5*$A26,5) -> 80 | F26: =MROUND($B$6*$A26,5) -> 190 | G26: =MROUND($B$7*$A26,5) -> 125 | H26: =MROUND($B$8*$A26,5) -> 85

Sheet Ramp-In Jun9-Jul19
A1: RAMP-IN · JUN 9 – JUL 19 · one small thing before class, every day
A2: 5/3/1 BBB is retired — from now until Week 1 (Jul 20), class is the training and this is the garnish. RULES: under 12 minutes · done BEFORE class · never to fatigue, never to failure, nothing should feel like a workout · miss a day, just pick up tomorrow (consistency beats completeness) · do NOT test anything — Week 1 of the plan is the test week. Meanwhile: lock in your partner, and remember registration opens Aug 1 (plan Week 2).
A4: DAY | B4: THE ONE THING (pre-class, ~10:00) | C4: WHY (what it feeds in the plan) | D4: LOADS / NOTES
A5: MON | B5: Shoulder armor — 2 rounds: 15 band face pulls · 10 table tops (:02 pause) · 12 banded external rotations/side · :30 dead hang | C5: The durability thread that runs the whole 26 weeks — keeps the rope-climb shoulder quiet before volume arrives | D5: Bands only. If anything pinches, smaller range, not more grit.
A6: TUE | B6: Jump rope cadence — 5:00 practice: 3–4 sets of 50–75 unbroken single-unders + 2 x 25 smooth double-unders | C6: Fort Sumter ran 75 SU you-go-I-go — SU speed is a scored skill at Novice | D6: Relaxed shoulders, wrists do the work. Count your biggest unbroken set weekly.
A7: WED | B7: Hang + midline — accumulate bar hang (target below) + 2 x 8 hanging leg raises, strict-ish | C7: JBC was a grip event (40 DB deadlifts → 30 pull-ups → CTB); leg raises were the Fort Sumter midline | D7: Mixed grip OK on hangs. Leg raises smooth, toes high, no swing.
A8: THU | B8: Barbell groove — E90s x 5: 1 clean & jerk, climbing to ~65–70% and stopping there | C8: Hunley/Moose is the most predictable test at FOTC — one weekly touch keeps the pattern oiled with zero fatigue | D8: ="~65–70% → "&MROUND(Maxes!$B$7*0.65,5)&"–"&MROUND(Maxes!$B$7*0.7,5)&" lb — crisp, never a grind" -> ~65–70% → 135–145 lb — crisp, never a grind
A9: FRI | B9: Wall + bar touch — 3 x 2 wall walks (perfect line) + 3 x 3 CTB (or pull-ups if CTB isn't smooth that day) | C9: The two gymnastics currencies of the last two championships, in maintenance doses | D9: Quality only. If Friday class is shoulder-heavy, cut to 2 rounds.
A10: SAT | B10: Easy engine — 20–30:00 Z2 (bike/row/jog/walk Ora) + 10:00 mobility: couch stretch · banded lat · t-spine over roller | C10: Aerobic base deposit for Block 1's run progression and the qualifier engine | D10: Conversational pace. This is the easiest thing you'll do all week — keep it that way.
A11: SUN | B11: OFF — walk, beach, nothing | C11: Recovery is the program | D11: —
A13: WEEK | B13: DATES | C13: DIAL (tiny progressions — everything else identical) | D13: CHECKPOINT
A14: R1 | B14: Jun 9–14 (starts today) | C14: Establish the habit. Baseline doses above; note where everything sits. | D14: Texted/talked to a potential partner?
A15: R2 | B15: Jun 15–21 | C15: Hangs: accumulate 1:30 total Wed. SU: biggest set +10. | D15: —
A16: R3 | B16: Jun 22–28 | C16: +1 round Mon shoulder circuit. Hangs: 2:00 total. | D16: Partner decided? Share this file — they enter their maxes.
A17: R4 | B17: Jun 29–Jul 5 | C17: C&J Thursday: 2 singles per interval (still ≤70%). Hangs: 2:30. | D17: July 4 week — beach counts as Saturday Z2.
A18: R5 | B18: Jul 6–12 | C18: Hold everything. Hangs: 3:00 total. DUs: 2 x 35 smooth. | D18: Gear check: rope, grips, lifters all in good shape?
A19: R6 | B19: Jul 13–19 | C19: EASE OFF — half doses Mon–Wed, skip Thu barbell, Fri touch only, Sat easy. | D19: Arrive at Jul 20 bored and fresh. Week 1 tests everything.

Sheet B1 Base W1-5
A1: B1 BASE W1-5
A2: Goal: rebuild strict gymnastics capacity, run a full strength wave, pour the aerobic base, and bulletproof the shoulder (face pulls / table tops / dead hangs show up constantly on purpose — the rope-climb flare-ups from last cycle don't get a vote this year). Structure: Mon Lower A · Tue Upper A · Wed Engine · Fri Upper B · Sat Lower B + run.
A4: WEEK | B4: DAY | C4: SESSION (layered on top of class unless noted) | D4: MAIN-LIFT LOADS (auto) | E4: RESULTS / FEEDBACK — log everything
A5: WEEK 1 · Jul 20–Jul 26 — BASELINE WEEK — test everything, log everything
A6: Mon Jul 20 | B6: MON | C6: LOWER A Prep — 3 rounds: 16 goblet cossack squats (loaded heel flat) · 10 back ext off GHD · 8 reverse Nordics BACK SQUAT: 1x2 @ 80% · 2x2 @ 82.5% · 2x1 @ 85% · 3x4 @ 65% (move the back-offs FAST) + 4 reactive DB jumps after each work set (recoil off the floor, be a bouncy ball) 3x8 Bulgarian split squats (DBs, add load weekly) 3x12 stiff-leg deadlift @ ~40–50% of DL 1RM (deep hamstring stretch) 3x20 kip swings (stiff midline — quality over shape size) Week 1 mindset: this week sets every trend line for the next 6 months. RPE honesty > heroics. | D6: ="80% → "&MROUND(Maxes!$B$2*0.8,5)&" lb"&" · "&"82.5% → "&MROUND(Maxes!$B$2*0.825,5)&" lb"&" · "&"85% → "&MROUND(Maxes!$B$2*0.85,5)&" lb"&" · "&"65% → "&MROUND(Maxes!$B$2*0.65,5)&" lb" -> 80% → 220 lb · 82.5% → 225 lb · 85% → 235 lb · 65% → 180 lb
A7: Tue Jul 21 | B7: TUE | C7: UPPER A Prep — 2 rounds: 15 banded straight-arm pull-downs · 10 table tops (:02 pause) · 1:00 banded lat stretch/side BENCH PRESS: 1x2 @ 80% · 2x2 @ 82.5% · 2x1 @ 85% · 3x4 @ 65% (move the back-offs FAST) PULL THREAD — TEST: 1 max set strict pull-ups (log on Benchmarks) · then E2MOM x4: 60% of that number HS THREAD — TEST: 1 max set strict HSPU + 1 max set kipping HSPU + 4:00 max wall walks (rest 3:00 between tests — log on Benchmarks) PRESS THREAD — EMOM 8: 8 Z press (hard-but-repeatable DB) 4 x (1 RIR) deficit pike push-ups, hands on DBs — record set sizes 4x12 straight-arm pull-downs Midline: EMOM 6: 6 light GHD sit-ups (plate behind head) | D7: ="80% → "&MROUND(Maxes!$B$4*0.8,5)&" lb"&" · "&"82.5% → "&MROUND(Maxes!$B$4*0.825,5)&" lb"&" · "&"85% → "&MROUND(Maxes!$B$4*0.85,5)&" lb"&" · "&"65% → "&MROUND(Maxes!$B$4*0.65,5)&" lb" -> 80% → 155 lb · 82.5% → 160 lb · 85% → 165 lb · 65% → 125 lb
A8: Wed Jul 22 | B8: WED | C8: ENGINE — TEST DAY 2k ROW TEST (log on Benchmarks — this sets your qualifier row paces: 5k pace ≈ 2k split + :07–:08) Then 15:00 easy spin/walk flush. Shoulder durability: 3 rounds — 20 band face pulls · 15 banded external rotations/side · :30 dead hang
A9: Fri Jul 24 | B9: FRI | C9: UPPER B Prep — 3 rounds: 8 SA upright rows · 8 SA DB push press (same DB) · 20 band face pulls (elbows wide) STRICT PRESS: 1x2 @ 80% · 2x2 @ 82.5% · 2x1 @ 85% · 3x4 @ 65% (move the back-offs FAST) 4x8–12 DB incline bench (neutral grip, simulating rings) 3 rounds: 15 reverse flys · 10–15 ring skull crushers · 10–15 supinated ring rows (bully yourself) 2 rounds: 12 table tops (:02 pause) · :20 supinated dead hang | D9: ="80% → "&MROUND(Maxes!$B$5*0.8,5)&" lb"&" · "&"82.5% → "&MROUND(Maxes!$B$5*0.825,5)&" lb"&" · "&"85% → "&MROUND(Maxes!$B$5*0.85,5)&" lb"&" · "&"65% → "&MROUND(Maxes!$B$5*0.65,5)&" lb" -> 80% → 110 lb · 82.5% → 110 lb · 85% → 115 lb · 65% → 90 lb
A10: Sat Jul 25 | B10: SAT | C10: LOWER B + ENGINE Prep — 3 rounds: 15 banded ham curls · 8 ATG split squats (hold rig) · 5 pause front squats (warm-up loads) FRONT SQUAT: 1x2 @ 80% · 2x2 @ 82.5% · 2x1 @ 85% · 3x4 @ 65% (move the back-offs FAST) RUN TEST: 8:00 jog warm-up + 4 x 400m @ strong-but-repeatable / 2:00 walk. Record every split (Benchmarks). | D10: ="80% → "&MROUND(Maxes!$B$3*0.8,5)&" lb"&" · "&"82.5% → "&MROUND(Maxes!$B$3*0.825,5)&" lb"&" · "&"85% → "&MROUND(Maxes!$B$3*0.85,5)&" lb"&" · "&"65% → "&MROUND(Maxes!$B$3*0.65,5)&" lb" -> 80% → 180 lb · 82.5% → 185 lb · 85% → 190 lb · 65% → 145 lb
A12: WEEK 2 · Jul 27–Aug 02 — Build
A13: Mon Jul 27 | B13: MON | C13: LOWER A Prep — 3 rounds: 16 goblet cossack squats (loaded heel flat) · 10 back ext off GHD · 8 reverse Nordics BACK SQUAT: 1x2 @ 82.5% · 2x2 @ 85% · 1x1 @ 87.5% · 1x1 @ 90% · 3x4 @ 67.5% + 4 reactive DB jumps after each work set (recoil off the floor, be a bouncy ball) 3x8 Bulgarian split squats (DBs, add load weekly) 3x12 stiff-leg deadlift @ ~40–50% of DL 1RM (deep hamstring stretch) 3x20 kip swings (stiff midline — quality over shape size) REGISTER for the Coastal Qualifier this week — Novice Team (opens Aug 1). Make sure your partner registers too.. | D13: ="82.5% → "&MROUND(Maxes!$B$2*0.825,5)&" lb"&" · "&"85% → "&MROUND(Maxes!$B$2*0.85,5)&" lb"&" · "&"87.5% → "&MROUND(Maxes!$B$2*0.875,5)&" lb"&" · "&"90% → "&MROUND(Maxes!$B$2*0.9,5)&" lb"&" · "&"67.5% → "&MROUND(Maxes!$B$2*0.675,5)&" lb" -> 82.5% → 225 lb · 85% → 235 lb · 87.5% → 240 lb · 90% → 250 lb · 67.5% → 185 lb
A14: Tue Jul 28 | B14: TUE | C14: UPPER A Prep — 2 rounds: 15 banded straight-arm pull-downs · 10 table tops (:02 pause) · 1:00 banded lat stretch/side BENCH PRESS: 1x2 @ 82.5% · 2x2 @ 85% · 1x1 @ 87.5% · 1x1 @ 90% · 3x4 @ 67.5% PULL THREAD — E2MOM x5: strict pull-ups — pick a number you can hold all 5 sets HS THREAD — Headstand practice 5 x challenging duration (pressure in palms vs fingers = your balance dial) PRESS THREAD — EMOM 8: 8 Z press (hard-but-repeatable DB) 4 x (1 RIR) deficit pike push-ups, hands on DBs — record set sizes 4x12 straight-arm pull-downs Midline: EMOM 6: 6 light GHD sit-ups (plate behind head) | D14: ="82.5% → "&MROUND(Maxes!$B$4*0.825,5)&" lb"&" · "&"85% → "&MROUND(Maxes!$B$4*0.85,5)&" lb"&" · "&"87.5% → "&MROUND(Maxes!$B$4*0.875,5)&" lb"&" · "&"90% → "&MROUND(Maxes!$B$4*0.9,5)&" lb"&" · "&"67.5% → "&MROUND(Maxes!$B$4*0.675,5)&" lb" -> 82.5% → 160 lb · 85% → 165 lb · 87.5% → 170 lb · 90% → 175 lb · 67.5% → 130 lb
A15: Wed Jul 29 | B15: WED | C15: ENGINE EMOM 30: odd = 15/12 cal machine (alternate bike/row) · even = rest Hold the SAME pace all 15 work minutes — nasal breathing as long as you can. This is base, not a test. Finisher: 300' backward sled drag, easy.
A16: Fri Jul 31 | B16: FRI | C16: UPPER B Prep — 3 rounds: 8 SA upright rows · 8 SA DB push press (same DB) · 20 band face pulls (elbows wide) STRICT PRESS: 1x2 @ 82.5% · 2x2 @ 85% · 1x1 @ 87.5% · 1x1 @ 90% · 3x4 @ 67.5% 4x8–12 DB incline bench (neutral grip, simulating rings) 3 rounds: 15 reverse flys · 10–15 ring skull crushers · 10–15 supinated ring rows (bully yourself) 2 rounds: 12 table tops (:02 pause) · :20 supinated dead hang | D16: ="82.5% → "&MROUND(Maxes!$B$5*0.825,5)&" lb"&" · "&"85% → "&MROUND(Maxes!$B$5*0.85,5)&" lb"&" · "&"87.5% → "&MROUND(Maxes!$B$5*0.875,5)&" lb"&" · "&"90% → "&MROUND(Maxes!$B$5*0.9,5)&" lb"&" · "&"67.5% → "&MROUND(Maxes!$B$5*0.675,5)&" lb" -> 82.5% → 110 lb · 85% → 115 lb · 87.5% → 120 lb · 90% → 120 lb · 67.5% → 90 lb
A17: Sat Aug 01 | B17: SAT | C17: LOWER B + ENGINE Prep — 3 rounds: 15 banded ham curls · 8 ATG split squats (hold rig) · 5 pause front squats (warm-up loads) FRONT SQUAT: 1x2 @ 82.5% · 2x2 @ 85% · 1x1 @ 87.5% · 1x1 @ 90% · 3x4 @ 67.5% Run: 10:00 jog + 5 x 400m / 2:00 walk — each rep :03–:05 faster than last week's average. | D17: ="82.5% → "&MROUND(Maxes!$B$3*0.825,5)&" lb"&" · "&"85% → "&MROUND(Maxes!$B$3*0.85,5)&" lb"&" · "&"87.5% → "&MROUND(Maxes!$B$3*0.875,5)&" lb"&" · "&"90% → "&MROUND(Maxes!$B$3*0.9,5)&" lb"&" · "&"67.5% → "&MROUND(Maxes!$B$3*0.675,5)&" lb" -> 82.5% → 185 lb · 85% → 190 lb · 87.5% → 195 lb · 90% → 205 lb · 67.5% → 150 lb
A19: WEEK 3 · Aug 03–Aug 09 — Heaviest base week
A20: Mon Aug 03 | B20: MON | C20: LOWER A Prep — 3 rounds: 16 goblet cossack squats (loaded heel flat) · 10 back ext off GHD · 8 reverse Nordics BACK SQUAT: 2x2 @ 85% · 2x2 @ 87.5% · 1x1 @ 90% · 1x1 @ 92.5% · 3x4 @ 70% + 4 reactive DB jumps after each work set (recoil off the floor, be a bouncy ball) 3x8 Bulgarian split squats (DBs, add load weekly) 3x12 stiff-leg deadlift @ ~40–50% of DL 1RM (deep hamstring stretch) 3x20 kip swings (stiff midline — quality over shape size) | D20: ="85% → "&MROUND(Maxes!$B$2*0.85,5)&" lb"&" · "&"87.5% → "&MROUND(Maxes!$B$2*0.875,5)&" lb"&" · "&"90% → "&MROUND(Maxes!$B$2*0.9,5)&" lb"&" · "&"92.5% → "&MROUND(Maxes!$B$2*0.925,5)&" lb"&" · "&"70% → "&MROUND(Maxes!$B$2*0.7,5)&" lb" -> 85% → 235 lb · 87.5% → 240 lb · 90% → 250 lb · 92.5% → 255 lb · 70% → 195 lb
A21: Tue Aug 04 | B21: TUE | C21: UPPER A Prep — 2 rounds: 15 banded straight-arm pull-downs · 10 table tops (:02 pause) · 1:00 banded lat stretch/side BENCH PRESS: 2x2 @ 85% · 2x2 @ 87.5% · 1x1 @ 90% · 1x1 @ 92.5% · 3x4 @ 70% PULL THREAD — E2MOM x6: strict pull-ups — same number as last week, one extra set HS THREAD — EMOM 5: :20 wall-facing HS hold — PERFECT line: quads flexed, toes pointed, only toes touch wall PRESS THREAD — EMOM 8: 8 Z press (hard-but-repeatable DB) 4 x (1 RIR) deficit pike push-ups, hands on DBs — record set sizes 4x12 straight-arm pull-downs Midline: EMOM 6: 6 light GHD sit-ups (plate behind head) | D21: ="85% → "&MROUND(Maxes!$B$4*0.85,5)&" lb"&" · "&"87.5% → "&MROUND(Maxes!$B$4*0.875,5)&" lb"&" · "&"90% → "&MROUND(Maxes!$B$4*0.9,5)&" lb"&" · "&"92.5% → "&MROUND(Maxes!$B$4*0.925,5)&" lb"&" · "&"70% → "&MROUND(Maxes!$B$4*0.7,5)&" lb" -> 85% → 165 lb · 87.5% → 170 lb · 90% → 175 lb · 92.5% → 180 lb · 70% → 135 lb
A22: Wed Aug 05 | B22: WED | C22: ENGINE For time: 3k bike · 100 double-unders · 2k row · 100 double-unders · 1k run Steady 80–85% — DUs in 2–3 sets max, relax the shoulders on the rope.
A23: Fri Aug 07 | B23: FRI | C23: UPPER B Prep — 3 rounds: 8 SA upright rows · 8 SA DB push press (same DB) · 20 band face pulls (elbows wide) STRICT PRESS: 2x2 @ 85% · 2x2 @ 87.5% · 1x1 @ 90% · 1x1 @ 92.5% · 3x4 @ 70% 4x8–12 DB incline bench (neutral grip, simulating rings) 3 rounds: 15 reverse flys · 10–15 ring skull crushers · 10–15 supinated ring rows (bully yourself) 2 rounds: 12 table tops (:02 pause) · :20 supinated dead hang | D23: ="85% → "&MROUND(Maxes!$B$5*0.85,5)&" lb"&" · "&"87.5% → "&MROUND(Maxes!$B$5*0.875,5)&" lb"&" · "&"90% → "&MROUND(Maxes!$B$5*0.9,5)&" lb"&" · "&"92.5% → "&MROUND(Maxes!$B$5*0.925,5)&" lb"&" · "&"70% → "&MROUND(Maxes!$B$5*0.7,5)&" lb" -> 85% → 115 lb · 87.5% → 120 lb · 90% → 120 lb · 92.5% → 125 lb · 70% → 95 lb
A24: Sat Aug 08 | B24: SAT | C24: LOWER B + ENGINE Prep — 3 rounds: 15 banded ham curls · 8 ATG split squats (hold rig) · 5 pause front squats (warm-up loads) FRONT SQUAT: 2x2 @ 85% · 2x2 @ 87.5% · 1x1 @ 90% · 1x1 @ 92.5% · 3x4 @ 70% Run: 10:00 jog + 2 x 800m / 3:00 walk — record times, you're beating these in two weeks. | D24: ="85% → "&MROUND(Maxes!$B$3*0.85,5)&" lb"&" · "&"87.5% → "&MROUND(Maxes!$B$3*0.875,5)&" lb"&" · "&"90% → "&MROUND(Maxes!$B$3*0.9,5)&" lb"&" · "&"92.5% → "&MROUND(Maxes!$B$3*0.925,5)&" lb"&" · "&"70% → "&MROUND(Maxes!$B$3*0.7,5)&" lb" -> 85% → 190 lb · 87.5% → 195 lb · 90% → 205 lb · 92.5% → 210 lb · 70% → 160 lb
A26: WEEK 4 · Aug 10–Aug 16 — DELOAD
A27: Mon Aug 10 | B27: MON | C27: LOWER A Prep — 3 rounds: 16 goblet cossack squats (loaded heel flat) · 10 back ext off GHD · 8 reverse Nordics BACK SQUAT: DELOAD: 2x2 @ 87.5% · 4x3 @ 80% — same intensity feel, way less volume + 4 reactive DB jumps after each work set (recoil off the floor, be a bouncy ball) 2x8 Bulgarian split squats · 2x12 stiff-leg deadlift (same load) · 2x15 kip swings | D27: ="87.5% → "&MROUND(Maxes!$B$2*0.875,5)&" lb"&" · "&"80% → "&MROUND(Maxes!$B$2*0.8,5)&" lb" -> 87.5% → 240 lb · 80% → 220 lb
A28: Tue Aug 11 | B28: TUE | C28: UPPER A Prep — 2 rounds: 15 banded straight-arm pull-downs · 10 table tops (:02 pause) · 1:00 banded lat stretch/side BENCH PRESS: DELOAD: 2x2 @ 87.5% · 4x3 @ 80% — same intensity feel, way less volume PULL THREAD — E2MOM x5: strict pull-ups — one rep UNDER last week, every set (deload means deload) HS THREAD — EMOM 4: :20 wall-facing HS hold (one set less) PRESS THREAD — EMOM 6: 8 Z press (same DB) 3 x (1 RIR) deficit pike push-ups 3x15 straight-arm pull-downs Midline: EMOM 6: 6 light GHD sit-ups (plate behind head) | D28: ="87.5% → "&MROUND(Maxes!$B$4*0.875,5)&" lb"&" · "&"80% → "&MROUND(Maxes!$B$4*0.8,5)&" lb" -> 87.5% → 170 lb · 80% → 155 lb
A29: Wed Aug 12 | B29: WED | C29: ENGINE — DELOAD 30–40:00 Z2 mix (bike/row/jog), conversational pace. 10:00 mobility flow: couch stretch · pigeon · banded lat stretch · t-spine over roller.
A30: Fri Aug 14 | B30: FRI | C30: UPPER B Prep — 3 rounds: 8 SA upright rows · 8 SA DB push press (same DB) · 20 band face pulls (elbows wide) STRICT PRESS: DELOAD: 2x2 @ 87.5% · 4x3 @ 80% — same intensity feel, way less volume 3x8–12 DB incline bench (same weight) 2 rounds: 15 reverse flys · 10 ring skull crushers · 10 supinated ring rows 2 rounds: 10 table tops · :20 dead hang | D30: ="87.5% → "&MROUND(Maxes!$B$5*0.875,5)&" lb"&" · "&"80% → "&MROUND(Maxes!$B$5*0.8,5)&" lb" -> 87.5% → 120 lb · 80% → 110 lb
A31: Sat Aug 15 | B31: SAT | C31: LOWER B + ENGINE Prep — 3 rounds: 15 banded ham curls · 8 ATG split squats (hold rig) · 5 pause front squats (warm-up loads) FRONT SQUAT: DELOAD: 2x2 @ 87.5% · 4x3 @ 80% — same intensity feel, way less volume DELOAD run: 20:00 easy jog + 4 x :15 strides. That's it. Walk Ora for the rest. | D31: ="87.5% → "&MROUND(Maxes!$B$3*0.875,5)&" lb"&" · "&"80% → "&MROUND(Maxes!$B$3*0.8,5)&" lb" -> 87.5% → 195 lb · 80% → 180 lb
A33: WEEK 5 · Aug 17–Aug 23 — Heavy-for-day singles
A34: Mon Aug 17 | B34: MON | C34: LOWER A Prep — 3 rounds: 16 goblet cossack squats (loaded heel flat) · 10 back ext off GHD · 8 reverse Nordics BACK SQUAT: 1x1 heavy for the day (NOT a max — a crisp 9/10) · 3x3 @ 80% · 2x6 @ 72.5% + 4 reactive DB jumps after each work set (recoil off the floor, be a bouncy ball) 3x8 Bulgarian split squats (DBs, add load weekly) 3x12 stiff-leg deadlift @ ~40–50% of DL 1RM (deep hamstring stretch) 3x20 kip swings (stiff midline — quality over shape size) | D34: ="80% → "&MROUND(Maxes!$B$2*0.8,5)&" lb"&" · "&"72.5% → "&MROUND(Maxes!$B$2*0.725,5)&" lb" -> 80% → 220 lb · 72.5% → 200 lb
A35: Tue Aug 18 | B35: TUE | C35: UPPER A Prep — 2 rounds: 15 banded straight-arm pull-downs · 10 table tops (:02 pause) · 1:00 banded lat stretch/side BENCH PRESS: 1x1 heavy for the day (NOT a max — a crisp 9/10) · 3x3 @ 80% · 2x6 @ 72.5% PULL THREAD — E2MOM x5: strict pull-ups +5 lb if last week felt clean HS THREAD — EMOM 5: :25 wall-facing HS hold PRESS THREAD — EMOM 8: 8 Z press (hard-but-repeatable DB) 4 x (1 RIR) deficit pike push-ups, hands on DBs — record set sizes 4x12 straight-arm pull-downs Midline: EMOM 6: 6 light GHD sit-ups (plate behind head) | D35: ="80% → "&MROUND(Maxes!$B$4*0.8,5)&" lb"&" · "&"72.5% → "&MROUND(Maxes!$B$4*0.725,5)&" lb" -> 80% → 155 lb · 72.5% → 140 lb
A36: Wed Aug 19 | B36: WED | C36: ENGINE Every 2:30 x 12, alternating: 1) 30/24 cal bike 2) 150' backward sled drag 3) 30/24 cal row 4) 150' plate push Grip + legs + lungs — the tank-push pattern starts here.
A37: Fri Aug 21 | B37: FRI | C37: UPPER B Prep — 3 rounds: 8 SA upright rows · 8 SA DB push press (same DB) · 20 band face pulls (elbows wide) STRICT PRESS: 1x1 heavy for the day (NOT a max — a crisp 9/10) · 3x3 @ 80% · 2x6 @ 72.5% 4x8–12 DB incline bench (neutral grip, simulating rings) 3 rounds: 15 reverse flys · 10–15 ring skull crushers · 10–15 supinated ring rows (bully yourself) 2 rounds: 12 table tops (:02 pause) · :20 supinated dead hang | D37: ="80% → "&MROUND(Maxes!$B$5*0.8,5)&" lb"&" · "&"72.5% → "&MROUND(Maxes!$B$5*0.725,5)&" lb" -> 80% → 110 lb · 72.5% → 100 lb
A38: Sat Aug 22 | B38: SAT | C38: LOWER B + ENGINE Prep — 3 rounds: 15 banded ham curls · 8 ATG split squats (hold rig) · 5 pause front squats (warm-up loads) FRONT SQUAT: 1x1 heavy for the day (NOT a max — a crisp 9/10) · 3x3 @ 80% · 2x6 @ 72.5% Run: 10:00 jog + 3 x 800m / 3:00 walk — beat Week 3's times. | D38: ="80% → "&MROUND(Maxes!$B$3*0.8,5)&" lb"&" · "&"72.5% → "&MROUND(Maxes!$B$3*0.725,5)&" lb" -> 80% → 180 lb · 72.5% → 165 lb

Sheet B2 Build W6-10
A1: B2 BUILD W6-10
A2: Goal: convert base strength into competition currency — heavy-for-day singles, the wall-walk progression (Novice Event 6 currency, with optional kipping HSPU skill work), ring dips, TNG clean & jerk cycling through the Novice ladder (95→185), and Saturday qualifier simulations (two are repeats of last year's Coastal Qualifier workouts so you get a direct fitness comparison). Friday strict press becomes push press — the comp movement. Week 10 is a real taper: trust it.
A4: WEEK | B4: DAY | C4: SESSION (layered on top of class unless noted) | D4: MAIN-LIFT LOADS (auto) | E4: RESULTS / FEEDBACK — log everything
A5: WEEK 6 · Aug 24–Aug 30 — Heavy singles + HSPU progression begins
A6: Mon Aug 24 | B6: MON | C6: LOWER A Prep — 3 rounds: 10 cossack squats · 5 BB good mornings + 5 BB back squat jumps BACK SQUAT: 1x1 heavy for the day · 3x3 @ 82.5% · 2x7 @ 72.5% 4x8 box step-ups (start loading) · 4x12 weighted back ext · 4x15 prone banded ham curls | D6: ="82.5% → "&MROUND(Maxes!$B$2*0.825,5)&" lb"&" · "&"72.5% → "&MROUND(Maxes!$B$2*0.725,5)&" lb" -> 82.5% → 225 lb · 72.5% → 200 lb
A7: Tue Aug 25 | B7: TUE | C7: UPPER A Prep — 2 rounds: 12 Lu raises · 10 hand-release push-ups · 10 table tops (:02 pause) BENCH PRESS: 1x1 heavy for the day · 3x3 @ 82.5% · 2x7 @ 72.5% After every bench work set: 6 strict pull-ups, chest-high pull WALL WALK PROGRESSION — E90s x 6: 2 wall walks + :03 hold at top, perfect line. Optional skill dev after: EMOM 4: 2–3 kipping HSPU (personal goal — not tested at Novice). 3x 10+12 drop-set lateral raises (10 heavy / rest :20 / 12 light, controlled) 3x12 weighted GHD sit-ups | D7: ="82.5% → "&MROUND(Maxes!$B$4*0.825,5)&" lb"&" · "&"72.5% → "&MROUND(Maxes!$B$4*0.725,5)&" lb" -> 82.5% → 160 lb · 72.5% → 140 lb
A8: Wed Aug 26 | B8: WED | C8: ENGINE + BARBELL CYCLING A) E2MOM x 8: 3 TNG clean & jerks, climbing 95 → 155 across the 8 sets. Smooth cycling, no press-outs — the Novice ladder runs 95→185, and the 2026 championship asked Novice teams for 30 reps @ 165 + a 4:00 AMRAP @ 185. This is the most predictable test at FOTC — treat it like rent. B) 4 x 3:00 on / 3:00 off: 15/12 cal ski or bike + max alt DB snatches 50 in remaining time (comp bell is 35 — train heavy, compete light) (Event 4&5 interval pattern). Score = total snatches. | D8: ="45% → "&MROUND(Maxes!$B$7*0.45,5)&" lb"&" · "&"75% → "&MROUND(Maxes!$B$7*0.75,5)&" lb" -> 45% → 90 lb · 75% → 155 lb
A9: Fri Aug 28 | B9: FRI | C9: UPPER B Prep — 3 rounds: 8 SA upright rows · 8 SA DB push press · 20 band face pulls PUSH PRESS: E2MOM x5 — 5 reps climbing to a heavy 5 Ring dip EMOM 8 — pick a set size you can repeat all 8 minutes; record it (baseline) E90s x5: 3 wall walks + :03 perfect hold at top 3 rounds: elevated-foot ring rows (beat last session) · 150' double-DB OH carry · 18 band pull-aparts
A10: Sat Aug 29 | B10: SAT | C10: CHAMPIONSHIP BARBELL SIM v1 — Hunley/Moose pattern, intro loads 30 clean & jerks @ 115 (4:00 cap) → rest exactly 1:00 → 4:00 AMRAP clean & jerks @ 135. Record both + your cycling strategy (TNG sets vs fast singles). Progresses to 135/155 in W21 and FULL comp loads 165/185 in the W24 sim. FS first: FRONT SQUAT 3x3 @ 80%. | D10: ="80% → "&MROUND(Maxes!$B$3*0.8,5)&" lb" -> 80% → 180 lb
A12: WEEK 7 · Aug 31–Sep 06 — Build
A13: Mon Aug 31 | B13: MON | C13: LOWER A Prep — 3 rounds: 10 cossack squats · 5 BB good mornings + 5 BB back squat jumps BACK SQUAT: 1x1 heavy for the day · 3x3 @ 85% · 2x8 @ 72.5% 3x8 box step-ups (heavier) · 3x12 weighted back ext (+load) · 3x15 prone banded ham curls | D13: ="85% → "&MROUND(Maxes!$B$2*0.85,5)&" lb"&" · "&"72.5% → "&MROUND(Maxes!$B$2*0.725,5)&" lb" -> 85% → 235 lb · 72.5% → 200 lb
A14: Tue Sep 01 | B14: TUE | C14: UPPER A Prep — 2 rounds: 12 Lu raises · 10 hand-release push-ups · 10 table tops (:02 pause) BENCH PRESS: 1x1 heavy for the day · 3x3 @ 85% · 2x8 @ 72.5% After every bench work set: 6 strict pull-ups, chest-high pull WALL WALK PROGRESSION — E90s x 6: 3 wall walks — smooth turnover, no dead time at the top. Optional: EMOM 4: 2 wall walks. 3x 10+12 drop-set lateral raises (10 heavy / rest :20 / 12 light, controlled) 3x12 weighted GHD sit-ups | D14: ="85% → "&MROUND(Maxes!$B$4*0.85,5)&" lb"&" · "&"72.5% → "&MROUND(Maxes!$B$4*0.725,5)&" lb" -> 85% → 165 lb · 72.5% → 140 lb
A15: Wed Sep 02 | B15: WED | C15: ENGINE + HS WALK EMOM 24: 1) 20' HS walk (5' unbroken segments minimum) 2) 15/12 cal bike 3) 10 burpee box get-overs 4) rest. HS walk under a working heart rate — exactly what Event 1 asks for.
A16: Fri Sep 04 | B16: FRI | C16: UPPER B Prep — 3 rounds: 8 SA upright rows · 8 SA DB push press · 20 band face pulls PUSH PRESS: 5/5/3/3/3 — climb to a heavy 3 + E:30 x 12: 1 deadlift @ 75% (crisp singles, perfect spine) Ring dip EMOM 8 — hold 4s across (or +1 from your baseline) E90s x5: 3 wall walks + :03 perfect hold at top 3 rounds: elevated-foot ring rows (beat last session) · 150' double-DB OH carry · 18 band pull-aparts | D16: ="75% → "&MROUND(Maxes!$B$6*0.75,5)&" lb" -> 75% → 235 lb
A17: Sat Sep 05 | B17: SAT | C17: QUALIFIER SIM #2 — last year's Qualifier WK4 repeat AMRAP 14: 15 knees-to-chest · 10 box jump overs 24 (step down) · 5 deadlifts 185 — the Novice version. Direct comparison to last October's score — log the delta. FS first: FRONT SQUAT 1x1 heavy for day + 3x3 @ 80%. | D17: ="80% → "&MROUND(Maxes!$B$3*0.8,5)&" lb" -> 80% → 180 lb
A19: WEEK 8 · Sep 07–Sep 13 — Max set of 4 + Labor Day
A20: Mon Sep 07 | B20: MON | C20: LOWER A Prep — 3 rounds: 10 cossack squats · 5 BB good mornings + 5 BB back squat jumps BACK SQUAT: Build to a MAX SET OF 4 · then 4x3 @ 75% (speed) 3x8 box step-ups · 3x12 weighted back ext · 3x8 goblet cossacks (load the stretch) LABOR DAY — if the gym's running Whitten, that replaces Wednesday's engine; squat still happens. | D20: ="75% → "&MROUND(Maxes!$B$2*0.75,5)&" lb" -> 75% → 205 lb
A21: Tue Sep 08 | B21: TUE | C21: UPPER A Prep — 2 rounds: 12 Lu raises · 10 hand-release push-ups · 10 table tops (:02 pause) BENCH PRESS: Build to a MAX SET OF 4 · then 4x3 @ 75% (speed) After every bench work set: 4 weighted strict pull-ups (+10 lb) WALL WALK PROGRESSION — E90s x 8: 3 wall walks — 24 total, every rep identical. Optional: EMOM 5: 3–4 kipping HSPU. 3x 10+12 drop-set lateral raises (10 heavy / rest :20 / 12 light, controlled) 3x12 weighted GHD sit-ups | D21: ="75% → "&MROUND(Maxes!$B$4*0.75,5)&" lb" -> 75% → 145 lb
A22: Wed Sep 09 | B22: WED | C22: WHITTEN — Labor Day tradition 5 RFT: 22 KB swings 55 · 22 box jumps 24 · 400m run · 22 burpees · 22 wall balls 20 Pace round 1 like it's round 4. Compare to last year's time if you logged it.
A23: Fri Sep 11 | B23: FRI | C23: UPPER B Prep — 3 rounds: 8 SA upright rows · 8 SA DB push press · 20 band face pulls PUSH PRESS: 3/3/3/3/3 — heavy triple + E:30 x 12: 1 deadlift @ 80% Ring dip EMOM 8 — +1 rep on at least 4 of the 8 sets E90s x5: 4 wall walks, no holds — smooth turnover 3 rounds: elevated-foot ring rows (beat last session) · 150' double-DB OH carry · 18 band pull-aparts | D23: ="80% → "&MROUND(Maxes!$B$6*0.8,5)&" lb" -> 80% → 250 lb
A24: Sat Sep 12 | B24: SAT | C24: LOWER B + ENGINE FRONT SQUAT: build to max set of 4 · then 3x3 @ 75%. Then: 25:00 running clock — 2-4-6-8-10 thruster 75 + gymnastic complex (1 TTB + 1 pull-up) · 200m run after each round; max thrusters with remaining time. | D24: ="75% → "&MROUND(Maxes!$B$3*0.75,5)&" lb" -> 75% → 170 lb
A26: WEEK 9 · Sep 14–Sep 20 — Last hard week
A27: Mon Sep 14 | B27: MON | C27: LOWER A Prep — 3 rounds: 10 cossack squats · 5 BB good mornings + 5 BB back squat jumps BACK SQUAT: 1x1 heavy single · 4x4 @ 80% 3x6 double-DB Bulgarian split squats · 3x:30 back ext hold (5–10 lb) · 3x8 reverse Nordics | D27: ="80% → "&MROUND(Maxes!$B$2*0.8,5)&" lb" -> 80% → 220 lb
A28: Tue Sep 15 | B28: TUE | C28: UPPER A Prep — 2 rounds: 12 Lu raises · 10 hand-release push-ups · 10 table tops (:02 pause) BENCH PRESS: 1x1 heavy single · 4x4 @ 80% After every bench work set: 4 weighted strict pull-ups (+10 lb) WALL WALK PROGRESSION — EMOM 8: 2 wall walks FAST, then after full rest: 4:00 max wall walks (compare to W1 baseline — this is Event 6 currency). 2x12 lateral raises · 2x10 GHD sit-ups | D28: ="80% → "&MROUND(Maxes!$B$4*0.8,5)&" lb" -> 80% → 155 lb
A29: Wed Sep 16 | B29: WED | C29: ENGINE + GRIP For max cals: 20:00 on machine (alternate bike/row by feel); E2MOM hop off and do 150' farmers carry (heavy). Grip endurance pays the bills on TTB/pull-up workouts.
A30: Fri Sep 18 | B30: FRI | C30: UPPER B Prep — 3 rounds: 8 SA upright rows · 8 SA DB push press · 20 band face pulls PUSH PRESS: 3/3/1/1/1 — heavy single-ish (9/10, no misses) + E:30 x 10: 1 deadlift @ 80% Ring dip EMOM 6 — hold last week's best number E90s x5: 4 wall walks, no holds — smooth turnover 3 rounds: elevated-foot ring rows (beat last session) · 150' double-DB OH carry · 18 band pull-aparts | D30: ="80% → "&MROUND(Maxes!$B$6*0.8,5)&" lb" -> 80% → 250 lb
A31: Sat Sep 19 | B31: SAT | C31: QUALIFIER SIM #3 — last year's Qualifier WK5 repeat 3 rounds: 40 single-unders · 20 jumping pull-ups → 2 rounds: 60 SU · 15 jumping C2B → 1 round: 120 SU · 10 pull-ups. 12:00 cap — the Novice version. Jumping pull-up CADENCE is a real score-mover at Novice — set bar/box height and rhythm BEFORE 3-2-1-go. FS first: FRONT SQUAT 4x4 @ 80%. | D31: ="80% → "&MROUND(Maxes!$B$3*0.8,5)&" lb" -> 80% → 180 lb
A33: WEEK 10 · Sep 21–Sep 27 — QUALIFIER TAPER — volume −40%
A34: Mon Sep 21 | B34: MON | C34: LOWER A Prep — 3 rounds: 10 cossack squats · 5 BB good mornings + 5 BB back squat jumps BACK SQUAT: TAPER: 2x2 @ 80% · 3x3 @ 70% — bar speed is the whole point 2x8 box step-ups (light) · 2x12 back ext (bodyweight) · mobility: 2:00 couch stretch/side | D34: ="80% → "&MROUND(Maxes!$B$2*0.8,5)&" lb"&" · "&"70% → "&MROUND(Maxes!$B$2*0.7,5)&" lb" -> 80% → 220 lb · 70% → 195 lb
A35: Tue Sep 22 | B35: TUE | C35: UPPER A Prep — 2 rounds: 12 Lu raises · 10 hand-release push-ups · 10 table tops (:02 pause) BENCH PRESS: TAPER: 2x2 @ 80% · 3x3 @ 70% — bar speed is the whole point After bench: 3x5 strict pull-ups, smooth WALL WALK PROGRESSION — TAPER: EMOM 4: 2 crisp wall walks. Touch the skill, don't spend it. 2x12 lateral raises · 2x10 GHD sit-ups | D35: ="80% → "&MROUND(Maxes!$B$4*0.8,5)&" lb"&" · "&"70% → "&MROUND(Maxes!$B$4*0.7,5)&" lb" -> 80% → 155 lb · 70% → 135 lb
A36: Wed Sep 23 | B36: WED | C36: TAPER PRIMER 3 x 2:00 @ Open pace / 3:00 easy spin between. Then FULL DRESS REHEARSAL of the qualifier warm-up protocol (see B3 tab header) so Friday Oct 2 is automatic. Logistics: confirm judge, camera angle + storage, Competition Corner login, scoresheet printed.
A37: Fri Sep 25 | B37: FRI | C37: UPPER B Prep — 3 rounds: 8 SA upright rows · 8 SA DB push press · 20 band face pulls PUSH PRESS: 3x3 @ moderate — bar speed only Ring dip EMOM 4 — easy 3s, stay fresh E90s x3: 2 wall walks, grease the pattern 3 rounds: elevated-foot ring rows (beat last session) · 150' double-DB OH carry · 18 band pull-aparts
A38: Sat Sep 26 | B38: SAT | C38: TAPER SATURDAY 20:00 easy Z2 + 3 short pickups (:30 @ Open pace). 10:00 mobility. Early night. Qualifier WK1 drops Thursday 7pm — you are ready; the hay is in the barn.

Sheet B3 Qualifier W11-15
A1: B3 QUALIFIER W11-15
A2: THE COASTAL QUALIFIER — Oct 1–28. Rhythm every week: THU 7pm ET release (watch the live drop, write a pacing plan) → FRI attempt #1 (treat it as THE score) → SAT recovery → MON decide on a repeat (only if points actually move you — emotional repeats burn the week) → TUE repeat window or maintenance → WED rest + SUBMIT by 9pm ET on Competition Corner (logged in). One secret week carries TWO workouts — keep Tue/Wed flexible. TEAM NOTES: your team score is the SUM of both partners' scores — both register (Novice Team), both submit individually, and the weaker score moves the leaderboard exactly as much as the stronger one, so partner consistency > solo heroics. You don't have to do the workout together, but syncing Friday attempts means you can judge and film each other. RECORD EVERY ATTEMPT — qualifiers get video requests after the qualifier ends. WARM-UP PROTOCOL (adapt to each workout — this is the structure that worked last year): 2 rounds @ workout pace: 2:00 on the workout's machine @ race pace + 6–8 reps of each gymnastics/barbell movement at workout loads → relax 2–3:00, salt + water → 1 round ABOVE race pace: ~20 cal + 4 reps of the hardest movement → set a 6–8:00 timer, then GO. Lungs should be hot and you should be a little worried you did too much. You didn't.
A4: WEEK | B4: DAY | C4: SESSION (layered on top of class unless noted) | D4: MAIN-LIFT LOADS (auto) | E4: RESULTS / FEEDBACK — log everything
A5: WEEK 11 · Sep 28–Oct 04 — QUALIFIER WK1 — releases Thu Oct 1
A6: Mon Sep 28 | B6: MON | C6: SHARPEN BACK SQUAT 3x2 @ 80% (fast) · EMOM 6: alternating 2 wall walks / 5 pull-ups · 10:00 Z2 flush. | D6: ="80% → "&MROUND(Maxes!$B$2*0.8,5)&" lb" -> 80% → 220 lb
A7: Tue Sep 29 | B7: TUE | C7: SHARPEN BENCH 3x2 @ 80% · 4:00 @ Open pace: 12 cal row + 6 burpees, repeat · done in 40:00 total. | D7: ="80% → "&MROUND(Maxes!$B$4*0.8,5)&" lb" -> 80% → 155 lb
A8: Wed Sep 30 | B8: WED | C8: PRIME 15:00 easy spin + 3 x :30 pickups · full mobility flow · equipment check: rope, grips, tape, chalk, camera mount, charged battery.
A9: Thu Oct 01 | B9: THU | C9: RELEASE NIGHT — Qualifier Workout 1 drops 7:00pm ET (live on YouTube). Watch the standards video twice. Write the pacing plan: target splits, planned set breaks, transition setup. Lay out equipment tonight. Morning: 20:00 Z2 + mobility only.
A10: Fri Oct 02 | B10: FRI | C10: QUALIFIER ATTEMPT #1 Full warm-up protocol (block header). Judge + camera rolling. Execute the plan — the first 20% of the workout should feel insultingly easy; that's correct pacing. Log: score, splits, where it broke, RPE.
A11: Sat Oct 03 | B11: SAT | C11: RECOVERY 30–40:00 Z2 (bike/row/walk Ora) + 15:00 mobility. Review attempt video once, note ONE fix, then put it away.
A13: WEEK 12 · Oct 05–Oct 11 — QUALIFIER WK2
A14: Mon Oct 05 | B14: MON | C14: LOWER MAINTENANCE + repeat decision BACK SQUAT 4x3 @ 75% — crisp, fast, done in 20 minutes. 3x8 weighted back ext · 3x8 goblet cossacks. Watch Friday's video: where did seconds leak? Repeat ONLY if a realistic improvement moves your leaderboard position. | D14: ="75% → "&MROUND(Maxes!$B$2*0.75,5)&" lb" -> 75% → 205 lb
A15: Tue Oct 06 | B15: TUE | C15: REPEAT WINDOW — or upper maintenance if the Friday score stands: BENCH 4x4 @ 75% · EMOM 6: 3 wall walks (smooth) · 3x12 band face pulls · :30 x 2 dead hang. If repeating: full warm-up protocol, execute the fix you identified Monday — don't freelance mid-workout. | D15: ="75% → "&MROUND(Maxes!$B$4*0.75,5)&" lb" -> 75% → 145 lb
A16: Wed Oct 07 | B16: WED | C16: REST + SUBMIT Score due 9:00pm ET tonight — submit on Competition Corner (make sure you're logged into YOUR profile), verify the video uploaded/saved, screenshot the confirmation. 10:00 easy mobility only. Eat. Sleep.
A17: Thu Oct 08 | B17: THU | C17: RELEASE NIGHT — Qualifier Workout 2 drops 7:00pm ET (live on YouTube). Watch the standards video twice. Write the pacing plan: target splits, planned set breaks, transition setup. Lay out equipment tonight. Morning: 20:00 Z2 + mobility only.
A18: Fri Oct 09 | B18: FRI | C18: QUALIFIER ATTEMPT #1 Full warm-up protocol (block header). Judge + camera rolling. Execute the plan — the first 20% of the workout should feel insultingly easy; that's correct pacing. Log: score, splits, where it broke, RPE.
A19: Sat Oct 10 | B19: SAT | C19: RECOVERY 30–40:00 Z2 (bike/row/walk Ora) + 15:00 mobility. Review attempt video once, note ONE fix, then put it away.
A21: WEEK 13 · Oct 12–Oct 18 — QUALIFIER WK3
A22: Mon Oct 12 | B22: MON | C22: LOWER MAINTENANCE + repeat decision BACK SQUAT 4x3 @ 75% — crisp, fast, done in 20 minutes. 3x8 weighted back ext · 3x8 goblet cossacks. Watch Friday's video: where did seconds leak? Repeat ONLY if a realistic improvement moves your leaderboard position. | D22: ="75% → "&MROUND(Maxes!$B$2*0.75,5)&" lb" -> 75% → 205 lb
A23: Tue Oct 13 | B23: TUE | C23: REPEAT WINDOW — or upper maintenance if the Friday score stands: BENCH 4x4 @ 75% · EMOM 6: 3 wall walks (smooth) · 3x12 band face pulls · :30 x 2 dead hang. If repeating: full warm-up protocol, execute the fix you identified Monday — don't freelance mid-workout. | D23: ="75% → "&MROUND(Maxes!$B$4*0.75,5)&" lb" -> 75% → 145 lb
A24: Wed Oct 14 | B24: WED | C24: REST + SUBMIT Score due 9:00pm ET tonight — submit on Competition Corner (make sure you're logged into YOUR profile), verify the video uploaded/saved, screenshot the confirmation. 10:00 easy mobility only. Eat. Sleep.
A25: Thu Oct 15 | B25: THU | C25: RELEASE NIGHT — Qualifier Workout 3 drops 7:00pm ET (live on YouTube). Watch the standards video twice. Write the pacing plan: target splits, planned set breaks, transition setup. Lay out equipment tonight. Morning: 20:00 Z2 + mobility only.
A26: Fri Oct 16 | B26: FRI | C26: QUALIFIER ATTEMPT #1 Full warm-up protocol (block header). Judge + camera rolling. Execute the plan — the first 20% of the workout should feel insultingly easy; that's correct pacing. Log: score, splits, where it broke, RPE.
A27: Sat Oct 17 | B27: SAT | C27: RECOVERY 30–40:00 Z2 (bike/row/walk Ora) + 15:00 mobility. Review attempt video once, note ONE fix, then put it away.
A29: WEEK 14 · Oct 19–Oct 25 — QUALIFIER WK4
A30: Mon Oct 19 | B30: MON | C30: LOWER MAINTENANCE + repeat decision BACK SQUAT 4x3 @ 75% — crisp, fast, done in 20 minutes. 3x8 weighted back ext · 3x8 goblet cossacks. Watch Friday's video: where did seconds leak? Repeat ONLY if a realistic improvement moves your leaderboard position. | D30: ="75% → "&MROUND(Maxes!$B$2*0.75,5)&" lb" -> 75% → 205 lb
A31: Tue Oct 20 | B31: TUE | C31: REPEAT WINDOW — or upper maintenance if the Friday score stands: BENCH 4x4 @ 75% · EMOM 6: 3 wall walks (smooth) · 3x12 band face pulls · :30 x 2 dead hang. If repeating: full warm-up protocol, execute the fix you identified Monday — don't freelance mid-workout. | D31: ="75% → "&MROUND(Maxes!$B$4*0.75,5)&" lb" -> 75% → 145 lb
A32: Wed Oct 21 | B32: WED | C32: REST + SUBMIT Score due 9:00pm ET tonight — submit on Competition Corner (make sure you're logged into YOUR profile), verify the video uploaded/saved, screenshot the confirmation. 10:00 easy mobility only. Eat. Sleep.
A33: Thu Oct 22 | B33: THU | C33: RELEASE NIGHT — Qualifier Workout 4 drops 7:00pm ET (live on YouTube). Watch the standards video twice. Write the pacing plan: target splits, planned set breaks, transition setup. Lay out equipment tonight. Morning: 20:00 Z2 + mobility only.
A34: Fri Oct 23 | B34: FRI | C34: QUALIFIER ATTEMPT #1 Full warm-up protocol (block header). Judge + camera rolling. Execute the plan — the first 20% of the workout should feel insultingly easy; that's correct pacing. Log: score, splits, where it broke, RPE.
A35: Sat Oct 24 | B35: SAT | C35: RECOVERY 30–40:00 Z2 (bike/row/walk Ora) + 15:00 mobility. Review attempt video once, note ONE fix, then put it away.
A37: WEEK 15 · Oct 26–Nov 01 — Final submission + transition
A38: Mon Oct 26 | B38: MON | C38: LOWER MAINTENANCE + repeat decision BACK SQUAT 4x3 @ 75% — crisp, fast, done in 20 minutes. 3x8 weighted back ext · 3x8 goblet cossacks. Watch Friday's video: where did seconds leak? Repeat ONLY if a realistic improvement moves your leaderboard position. | D38: ="75% → "&MROUND(Maxes!$B$2*0.75,5)&" lb" -> 75% → 205 lb
A39: Tue Oct 27 | B39: TUE | C39: REPEAT WINDOW — or upper maintenance if the Friday score stands: BENCH 4x4 @ 75% · EMOM 6: 3 wall walks (smooth) · 3x12 band face pulls · :30 x 2 dead hang. If repeating: full warm-up protocol, execute the fix you identified Monday — don't freelance mid-workout. Last realistic repeat window of the qualifier. | D39: ="75% → "&MROUND(Maxes!$B$4*0.75,5)&" lb" -> 75% → 145 lb
A40: Wed Oct 28 | B40: WED | C40: FINAL SUBMISSION — all scores locked 9:00pm ET tonight (Oct 28). Save/back up every workout video — FOTC emails video requests to qualifiers. Then: done. Recovery mode.
A41: Thu Oct 29 | B41: THU | C41: OFF. Sleep in. Eat real food. Walk.
A42: Fri Oct 30 | B42: FRI | C42: ACTIVE RECOVERY 40:00 Z2 + full-body mobility (30:00). Write the weakness list while the qualifier is fresh: which workouts cost you, which movement, which minute.
A43: Sat Oct 31 | B43: SAT | C43: FUN DAY Class only, or something outside. The rebuild starts Monday — show up hungry.

Sheet B4 Rebuild W16-20
A1: B4 REBUILD W16-20
A2: Goal: biggest strength block of the cycle + attack exactly what the qualifier exposed. Week 16 is a structured audit — retest the gymnastics maxes and log them on the Benchmarks tab, then weeks 17–18 push load while the Olympic-lift thread (snatch week → clean week) rebuilds positions for the Championship barbell. Week 19 = Thanksgiving deload. Week 20 = MAX TESTING WEEK — new 1RMs across the board, then UPDATE THE MAXES TAB so the championship block calculates off real numbers.
A4: WEEK | B4: DAY | C4: SESSION (layered on top of class unless noted) | D4: MAIN-LIFT LOADS (auto) | E4: RESULTS / FEEDBACK — log everything
A5: WEEK 16 · Nov 02–Nov 08 — Volume reset + WEAKNESS AUDIT
A6: Mon Nov 02 | B6: MON | C6: LOWER A — volume reset Prep — 3 rounds: 16 goblet cossacks · 10 back ext · 8 reverse Nordics BACK SQUAT 5x5 @ 72.5% (every rep identical) 3x8 Bulgarian split squats · 3x12 stiff-leg DL · 3x15 banded ham curls | D6: ="72.5% → "&MROUND(Maxes!$B$2*0.725,5)&" lb" -> 72.5% → 200 lb
A7: Tue Nov 03 | B7: TUE | C7: UPPER A + GYMNASTICS AUDIT BENCH 5x5 @ 72.5% AUDIT (full rest between, log on Benchmarks W16 column): · 1 max set kipping pull-ups · 1 max set CTB · max wall walks in 4:00 · 1 max set ring dips 3x12 band face pulls · 2x:30 dead hang | D7: ="72.5% → "&MROUND(Maxes!$B$4*0.725,5)&" lb" -> 72.5% → 140 lb
A8: Wed Nov 04 | B8: WED | C8: OLY TECH + ENGINE E90s x 12: sets 1–4 clean pull + hang clean (pause :02 in catch) · 5–8 power clean singles · 9–12 squat clean. Climb only while positions stay perfect. Then 30:00 Z2.
A9: Fri Nov 06 | B9: FRI | C9: UPPER B STRICT PRESS 5x5 @ 72.5% Ring dip EMOM 8 (restart the thread at your audit number −1) E90s x4: 3 wall walks + :03 hold 3 rounds: elevated-foot ring rows · 150' double-DB OH carry · 18 pull-aparts | D9: ="72.5% → "&MROUND(Maxes!$B$5*0.725,5)&" lb" -> 72.5% → 100 lb
A10: Sat Nov 07 | B10: SAT | C10: LOWER B + AUDIT FRONT SQUAT 5x5 @ 72.5% 4:00 MAX WALL WALKS retest (Benchmarks) · then 5k row @ steady (compare pace to your W1 2k — should be ~2k split +:10–12) | D10: ="72.5% → "&MROUND(Maxes!$B$3*0.725,5)&" lb" -> 72.5% → 165 lb
A12: WEEK 17 · Nov 09–Nov 15 — Build · snatch week · threshold engine
A13: Mon Nov 09 | B13: MON | C13: LOWER A BACK SQUAT 4x4 @ 77.5% · 1x3 @ 82.5% 4x8 box step-ups (loaded) · 4x12 weighted back ext · 4x15 prone banded ham curls | D13: ="77.5% → "&MROUND(Maxes!$B$2*0.775,5)&" lb"&" · "&"82.5% → "&MROUND(Maxes!$B$2*0.825,5)&" lb" -> 77.5% → 215 lb · 82.5% → 225 lb
A14: Tue Nov 10 | B14: TUE | C14: UPPER A BENCH 4x4 @ 77.5% · 1x3 @ 82.5% · after each work set: 4 weighted strict pull-ups (+10) WEAKNESS SLOT #1 — 8–10:00 quality EMOM on the worst thing from the audit (e.g., wall walks: E90s x 8: 3; pull-up cycling: EMOM 8: 8–10) 3x 10+12 drop-set lateral raises · 3x12 weighted GHD | D14: ="77.5% → "&MROUND(Maxes!$B$4*0.775,5)&" lb"&" · "&"82.5% → "&MROUND(Maxes!$B$4*0.825,5)&" lb" -> 77.5% → 150 lb · 82.5% → 160 lb
A15: Wed Nov 11 | B15: WED | C15: OLY TECH + THRESHOLD E90s x 12: sets 1–4 snatch pull + hang snatch · 5–8 power snatch singles · 9–12 squat snatch. Then E2MOM x 4: 6 OHS @ 50% of day's heavy. Engine: 3 x 8:00 @ threshold (row/bike/ski rotate) / 3:00 easy.
A16: Fri Nov 13 | B16: FRI | C16: UPPER B PUSH PRESS 5/5/3/3/3 to a heavy 3 · E:30 x 12: 1 deadlift @ 80% Ring dip EMOM 8 (+1 over W16) E90s x5: 4 wall walks no holds 3 rounds: ring rows · 150' DB OH carry · 18 pull-aparts | D16: ="80% → "&MROUND(Maxes!$B$6*0.8,5)&" lb" -> 80% → 250 lb
A17: Sat Nov 14 | B17: SAT | C17: LOWER B + CAPACITY FRONT SQUAT 4x4 @ 77.5% Metcon — AMRAP 14: 10 alt DB snatch 50 (comp bell is 35) · 10 burpee box jump-overs 24 · 15/12 cal machine. Negative split it: rounds 5+ faster than rounds 1–4. | D17: ="77.5% → "&MROUND(Maxes!$B$3*0.775,5)&" lb" -> 77.5% → 175 lb
A19: WEEK 18 · Nov 16–Nov 22 — Heaviest rebuild week · clean week
A20: Mon Nov 16 | B20: MON | C20: LOWER A BACK SQUAT 4x3 @ 82.5% · 1x2 @ 87.5% 3x8 box step-ups (heaviest yet) · 3x12 weighted back ext · 3x8 reverse Nordics (plate behind head) | D20: ="82.5% → "&MROUND(Maxes!$B$2*0.825,5)&" lb"&" · "&"87.5% → "&MROUND(Maxes!$B$2*0.875,5)&" lb" -> 82.5% → 225 lb · 87.5% → 240 lb
A21: Tue Nov 17 | B21: TUE | C21: UPPER A BENCH 4x3 @ 82.5% · 1x2 @ 87.5% · after each work set: 4 weighted strict pull-ups (+15) WEAKNESS SLOT #2 (same target as W17, +1 rep or +1 set) 3x12 lateral raises · 3x10 weighted GHD | D21: ="82.5% → "&MROUND(Maxes!$B$4*0.825,5)&" lb"&" · "&"87.5% → "&MROUND(Maxes!$B$4*0.875,5)&" lb" -> 82.5% → 160 lb · 87.5% → 170 lb
A22: Wed Nov 18 | B22: WED | C22: OLY TECH + GRIP ENGINE E90s x 10: 1 clean + 1 front squat + 1 jerk, climbing to a heavy complex. Then Coffland-style: accumulate 4:00 bar hang; every break = 400m run + 20 push-ups.
A23: Fri Nov 20 | B23: FRI | C23: UPPER B PUSH PRESS 3/3/3/3/3 heavy triple · E:30 x 12: 1 deadlift @ 85% Ring dip EMOM 8 (hold W17's best) E90s x5: 4 wall walks 3 rounds: ring rows · 150' DB OH carry (one size up) · 18 pull-aparts | D23: ="85% → "&MROUND(Maxes!$B$6*0.85,5)&" lb" -> 85% → 270 lb
A24: Sat Nov 21 | B24: SAT | C24: LOWER B + CAPACITY FRONT SQUAT 4x3 @ 82.5% Metcon — 3 RFT: 400m run · 12 TTB (comp standard is knees-to-chest — train the harder one) · 9 thrusters 95 · 6 pull-ups. Smooth is fast. | D24: ="82.5% → "&MROUND(Maxes!$B$3*0.825,5)&" lb" -> 82.5% → 185 lb
A26: WEEK 19 · Nov 23–Nov 29 — THANKSGIVING DELOAD — travel-friendly
A27: Mon Nov 23 | B27: MON | C27: FULL-BODY DB (anywhere) 3 rounds easy: 10 DB RDL · 10 DB bench or push-ups · 10 goblet squats · 10 DB rows/arm · :30 plank. 25:00 cap, conversational.
A28: Tue Nov 24 | B28: TUE | C28: 30:00 easy run or brisk Ora walk + 10:00 mobility.
A29: Wed Nov 25 | B29: WED | C29: OFF — travel/prep day.
A30: Thu Nov 26 | B30: THU | C30: THANKSGIVING — Whitten (5 RFT: 22 KBS · 22 box jumps · 400m run · 22 burpees · 22 wall balls) with whoever's around, or a local turkey trot. Then eat everything; you're testing maxes Monday and glycogen is your friend.
A31: Sat Nov 28 | B31: SAT | C31: 20–30:00 Z2 + 3 x :15 strides + 5 light singles of squat/bench groove if equipment available. Prime, don't train.
A33: WEEK 20 · Nov 30–Dec 06 — MAX TESTING WEEK — update the Maxes tab with every new number
A34: Mon Nov 30 | B34: MON | C34: TEST — BACK SQUAT 1RM Full warm-up ladder (bar x10, 50%x5, 65%x3, 75%x2, 85%x1, 92%x1, then attempts). 3 attempts max past 92%. Log on Benchmarks + UPDATE MAXES TAB. | D34: ="85% → "&MROUND(Maxes!$B$2*0.85,5)&" lb"&" · "&"92.5% → "&MROUND(Maxes!$B$2*0.925,5)&" lb" -> 85% → 235 lb · 92.5% → 255 lb
A35: Tue Dec 01 | B35: TUE | C35: TEST — BENCH 1RM + max set strict pull-ups (fresh, after bench). Same ladder structure. Spotter or safeties, no hero grinds — a 5 lb PR counts the same as a 15 lb miss doesn't. | D35: ="85% → "&MROUND(Maxes!$B$4*0.85,5)&" lb"&" · "&"92.5% → "&MROUND(Maxes!$B$4*0.925,5)&" lb" -> 85% → 165 lb · 92.5% → 180 lb
A36: Wed Dec 02 | B36: WED | C36: TEST — CLEAN & JERK heavy single, then SNATCH heavy single (15:00 each). These set the championship barbell percentages — update Maxes tab.
A37: Fri Dec 04 | B37: FRI | C37: TEST — STRICT PRESS 1RM + max set ring dips. Then 3x5 @ 70% of the NEW max to groove it. | D37: ="85% → "&MROUND(Maxes!$B$5*0.85,5)&" lb" -> 85% → 115 lb
A38: Sat Dec 05 | B38: SAT | C38: TEST — FRONT SQUAT heavy single + 1-mile run retest (vs W1 400s — different test, same engine; log it). Sunday fully off. Champ prep starts Monday on fresh numbers. | D38: ="85% → "&MROUND(Maxes!$B$3*0.85,5)&" lb" -> 85% → 190 lb

Sheet B5 Champ Prep W21-24
A1: B5 CHAMP PREP W21-24
A2: Goal: turn fitness into Championship performance. Every Friday/Saturday is built from the ACTUAL 2026 Novice team events — Fort Sumter, Hunley+Moose, JBC, D-Day — converted to solo: worm thrusters → light barbell · synchro/you-go-I-go → 1:1 work:rest · partner machine splits → alternating machines. Whenever a class partner is around, run the synchro versions for real: synchro timing is free points most teams throw away. Strength drops to two short maintenance touches per week off the NEW maxes. Christmas week is condensed on purpose. Week 24 ends with a full two-day competition simulation — warm-ups, food timing, between-event recovery, everything dress-rehearsed.
A4: WEEK | B4: DAY | C4: SESSION (layered on top of class unless noted) | D4: MAIN-LIFT LOADS (auto) | E4: RESULTS / FEEDBACK — log everything
A5: WEEK 21 · Dec 07–Dec 13 — Event patterns begin (off new maxes)
A6: Mon Dec 07 | B6: MON | C6: STRENGTH TOUCH + TANK PUSH PATTERN BACK SQUAT 3x3 @ 82.5% (new max) 6 x 120' HEAVY sled push / 2:00 rest — low and grinding, Event 1 legs. 3x8 weighted back ext · 3x8 goblet cossacks | D6: ="82.5% → "&MROUND(Maxes!$B$2*0.825,5)&" lb" -> 82.5% → 225 lb
A7: Tue Dec 08 | B7: TUE | C7: STRENGTH TOUCH + HSPU/WALL-WALK DENSITY BENCH 3x3 @ 82.5% + 4 strict pull-ups after each set E90s x 8, alternating: A) 6 CTB + 8 hanging leg raises B) 3 wall walks. 2026 went hard on hanging gymnastics (JBC: 30 pull-ups → 15 CTB) but wall work has ruled past years — train both 3x12 face pulls · 2x:30 dead hang | D7: ="82.5% → "&MROUND(Maxes!$B$4*0.825,5)&" lb" -> 82.5% → 160 lb
A8: Wed Dec 09 | B8: WED | C8: SKI/ROW INTERVALS — Event 4&5 sim 4 x 3:00 on / 3:00 off: 200m run buy-in → max cal ski (or row). Score = total cals; aim for <2 cal fade across rounds. Midline: 3 rounds — :40 hollow hold · 12 KB side bends/side
A9: Fri Dec 11 | B9: FRI | C9: EVENT 2 → EVENT 3 FULL SIM (the back-to-back) HUNLEY + MOOSE SIM v2 (2026 format, build loads) 30 clean & jerks @ 135 (4:00 cap) → rest exactly 1:00 → 4:00 AMRAP clean & jerks @ 155. Practice the plate change INSIDE the 1:00 rest — in 2026 you swapped your own plates (+2x25, −2x15). Log both scores + strategy. Full comp loads (165/185) hit in the W24 sim. | D9: ="65% → "&MROUND(Maxes!$B$7*0.65,5)&" lb"&" · "&"75% → "&MROUND(Maxes!$B$7*0.75,5)&" lb" -> 65% → 135 lb · 75% → 155 lb
A10: Sat Dec 12 | B10: SAT | C10: FORT SUMTER SOLO + LEGACY CARRIES 2 RFT (8:00 cap): 75 single-unders · 10 box jump overs 24 (step down) · 10 hanging leg raises — the 2026 Saturday opener, solo-scaled. SU cadence and BJO rhythm ARE the score. Then 4 rounds easy-strong: 120' sled push · 40' double-DB OH carry 2x50 (pushes/carries ruled prior years — don't let them surprise you). Then 10:00 Z2 flush.
A12: WEEK 22 · Dec 14–Dec 20 — Heavier sims + capacity
A13: Mon Dec 14 | B13: MON | C13: STRENGTH TOUCH + LUNGE/JUMP BACK SQUAT 2x3 @ 85% E3MOM x 5: 8 front-rack walking lunges (135) + 6 box jumps (step down). 3x12 weighted back ext | D13: ="85% → "&MROUND(Maxes!$B$2*0.85,5)&" lb" -> 85% → 235 lb
A14: Tue Dec 15 | B14: TUE | C14: STRENGTH TOUCH + GYMNASTICS COMPLEX BENCH 2x3 @ 85% E90s x 6: 5 pull-ups + 3 CTB + 7 leg raises WITHOUT dropping off the bar (JBC closed with 15 CTB after 30 pull-ups and 40 DB deadlifts — grip complexes are the prep). EMOM 6: 3 wall walks — repeatable 3s should feel boring now. | D14: ="85% → "&MROUND(Maxes!$B$4*0.85,5)&" lb" -> 85% → 165 lb
A15: Wed Dec 16 | B15: WED | C15: D-DAY SOLO (2026 format) 4 x 3:00 AMRAP / :30 rest: 12/10 cal bike (alternate rower 16/13 by round) · 5 burpees over the bar · max thrusters 95 in remaining time. Score = total thrusters. The 2026 tiebreak was ROUND-4 thrusters — build the pacing so round 4 is your biggest round. (Worm @ 120 split two ways ≈ a light, fast bar.)
